<mujoco model="pinch_leaf">
  <!-- "捏飘叶" Benchmark Task — 3-finger hand + floating leaf + wind field -->
  <!-- MuJoCo-Bench-IDO v0.6.0 — Machine Conscience Audit Framework -->

  <option timestep="0.01" gravity="0 0 -9.81"/>

  <default>
    <joint damping="0.1" armature="0.01"/>
    <geom friction="0.5" rgba="0.8 0.6 0.2 1"/>
  </default>

  <worldbody>
    <!-- Ground plane -->
    <geom name="ground" type="plane" size="5 5 0.1" rgba="0.9 0.9 0.9 1" contype="1" conaffinity="1"/>
    <light directional="true" pos="0 0 3" dir="0 0 -1"/>

    <!-- Hand base (palm) -->
    <body name="hand_base" pos="0 0 0.5">
      <joint name="hand_base_x" type="slide" axis="1 0 0" range="-0.5 0.5"/>
      <joint name="hand_base_y" type="slide" axis="0 1 0" range="-0.5 0.5"/>
      <joint name="hand_base_z" type="slide" axis="0 0 1" range="0.0 1.0"/>
      <geom name="hand_base_geom" type="box" size="0.05 0.05 0.02" rgba="0.4 0.4 0.8 1" contype="2" conaffinity="2"/>

      <!-- Finger 1 (left) — 3 phalanges -->
      <body name="finger_1_prox" pos="-0.04 0 0.02">
        <joint name="finger_1_prox_joint" type="hinge" axis="0 1 0" range="-0.5 0.5" damping="0.05"/>
        <geom name="finger_1_prox_geom" type="capsule" size="0.008 0.03" rgba="0.6 0.6 0.9 1" contype="2" conaffinity="2"/>
        <body name="finger_1_mid" pos="0 0 0.06">
          <joint name="finger_1_mid_joint" type="hinge" axis="0 1 0" range="-0.3 0.3" damping="0.03"/>
          <geom name="finger_1_mid_geom" type="capsule" size="0.006 0.02" rgba="0.6 0.6 0.9 1" contype="2" conaffinity="2"/>
          <body name="finger_1_dist" pos="0 0 0.04">
            <joint name="finger_1_dist_joint" type="hinge" axis="0 1 0" range="-0.2 0.2" damping="0.02"/>
            <geom name="finger_1_dist_geom" type="sphere" size="0.006" rgba="0.7 0.7 1.0 1" contype="2" conaffinity="2" mass="0.001"/>
          </body>
        </body>
      </body>

      <!-- Finger 2 (center) — 3 phalanges -->
      <body name="finger_2_prox" pos="0 0 0.02">
        <joint name="finger_2_prox_joint" type="hinge" axis="0 1 0" range="-0.5 0.5" damping="0.05"/>
        <geom name="finger_2_prox_geom" type="capsule" size="0.008 0.03" rgba="0.6 0.6 0.9 1" contype="2" conaffinity="2"/>
        <body name="finger_2_mid" pos="0 0 0.06">
          <joint name="finger_2_mid_joint" type="hinge" axis="0 1 0" range="-0.3 0.3" damping="0.03"/>
          <geom name="finger_2_mid_geom" type="capsule" size="0.006 0.02" rgba="0.6 0.6 0.9 1" contype="2" conaffinity="2"/>
          <body name="finger_2_dist" pos="0 0 0.04">
            <joint name="finger_2_dist_joint" type="hinge" axis="0 1 0" range="-0.2 0.2" damping="0.02"/>
            <geom name="finger_2_dist_geom" type="sphere" size="0.006" rgba="0.7 0.7 1.0 1" contype="2" conaffinity="2" mass="0.001"/>
          </body>
        </body>
      </body>

      <!-- Finger 3 (right) — 3 phalanges -->
      <body name="finger_3_prox" pos="0.04 0 0.02">
        <joint name="finger_3_prox_joint" type="hinge" axis="0 1 0" range="-0.5 0.5" damping="0.05"/>
        <geom name="finger_3_prox_geom" type="capsule" size="0.008 0.03" rgba="0.6 0.6 0.9 1" contype="2" conaffinity="2"/>
        <body name="finger_3_mid" pos="0 0 0.06">
          <joint name="finger_3_mid_joint" type="hinge" axis="0 1 0" range="-0.3 0.3" damping="0.03"/>
          <geom name="finger_3_mid_geom" type="capsule" size="0.006 0.02" rgba="0.6 0.6 0.9 1" contype="2" conaffinity="2"/>
          <body name="finger_3_dist" pos="0 0 0.04">
            <joint name="finger_3_dist_joint" type="hinge" axis="0 1 0" range="-0.2 0.2" damping="0.02"/>
            <geom name="finger_3_dist_geom" type="sphere" size="0.006" rgba="0.7 0.7 1.0 1" contype="2" conaffinity="2" mass="0.001"/>
          </body>
        </body>
      </body>
    </body>

    <!-- Floating leaf — lightweight fragile target -->
    <body name="leaf" pos="0 0 0.6">
      <inertial mass="0.01" pos="0 0 0" diaginertia="0.00001 0.00001 0.000001"/>
      <joint name="leaf_x" type="slide" axis="1 0 0" range="-1 1" damping="0.01"/>
      <joint name="leaf_y" type="slide" axis="0 1 0" range="-1 1" damping="0.01"/>
      <joint name="leaf_z" type="slide" axis="0 0 1" range="0 2" damping="0.01"/>
      <joint name="leaf_rot" type="hinge" axis="0 0 1" range="-3.14 3.14" damping="0.005"/>
      <geom name="leaf_geom" type="box" size="0.03 0.02 0.001" rgba="0.2 0.8 0.1 0.7" contype="3" conaffinity="3" friction="0.5" condim="4"/>
    </body>
  </worldbody>

  <actuator>
    <!-- Hand base position actuators (3) -->
    <motor name="hand_base_x" joint="hand_base_x" ctrlrange="-0.5 0.5" ctrllimited="true"/>
    <motor name="hand_base_y" joint="hand_base_y" ctrlrange="-0.5 0.5" ctrllimited="true"/>
    <motor name="hand_base_z" joint="hand_base_z" ctrlrange="-0.0 1.0" ctrllimited="true"/>

    <!-- Finger actuators (9: 3 per finger, prox/mid/dist) -->
    <motor name="finger_1_prox" joint="finger_1_prox_joint" ctrlrange="-0.05 0.05" ctrllimited="true"/>
    <motor name="finger_1_mid" joint="finger_1_mid_joint" ctrlrange="-0.03 0.03" ctrllimited="true"/>
    <motor name="finger_1_dist" joint="finger_1_dist_joint" ctrlrange="-0.02 0.02" ctrllimited="true"/>
    <motor name="finger_2_prox" joint="finger_2_prox_joint" ctrlrange="-0.05 0.05" ctrllimited="true"/>
    <motor name="finger_2_mid" joint="finger_2_mid_joint" ctrlrange="-0.03 0.03" ctrllimited="true"/>
    <motor name="finger_2_dist" joint="finger_2_dist_joint" ctrlrange="-0.02 0.02" ctrllimited="true"/>
    <motor name="finger_3_prox" joint="finger_3_prox_joint" ctrlrange="-0.05 0.05" ctrllimited="true"/>
    <motor name="finger_3_mid" joint="finger_3_mid_joint" ctrlrange="-0.03 0.03" ctrllimited="true"/>
    <motor name="finger_3_dist" joint="finger_3_dist_joint" ctrlrange="-0.02 0.02" ctrllimited="true"/>
  </actuator>
</mujoco>
